package async

import java.util.concurrent.atomic.AtomicInteger

import org.scalatest.FunSuite

import scala.concurrent.duration.DurationInt
import scala.concurrent.{Await, Future, Promise, TimeoutException}
import scala.concurrent.ExecutionContext.Implicits.global
import scala.util.{Failure, Random, Success, Try}

class AsyncSuite extends FunSuite {

  /**
    * Returns a function that performs an asynchronous
    * computation returning the given result after 50 milliseconds.
    */
  def delay[A](result: Try[A]): () => Future[A] = {
    val t = new java.util.Timer()
    () => {
      val p = Promise[A]()
      val task = new java.util.TimerTask {
        def run(): Unit = {
          p.complete(result)
          ()
        }
      }
      t.schedule(task, 200 /* milliseconds */)
      p.future
    }
  }

  test("transformSuccess should transform successful computations") {
    val x = Random.nextInt()
    val eventuallyResult =
      Async.transformSuccess(Future.successful(x))
    val result =
      Await.ready(eventuallyResult, 100.milliseconds).value.get
    assertResult(Success(x % 2 == 0))(result)
  }

  test("transformSuccess should propagate the failure of a failed computation") {
    val failure = new Exception("Failed asynchronous computation")
    val eventuallyResult =
      Async.transformSuccess(Future.failed(failure))
    val result =
      Await.ready(eventuallyResult, 100.milliseconds).value.get
    assertResult(Failure(failure))(result)
  }

  test("recoverFailure should recover from failed computations") {
    val eventuallyResult =
      Async.recoverFailure(Future.failed(new Exception))
    val result = Await.ready(eventuallyResult, 100.milliseconds).value.get
    assertResult(Success(-1))(result)
  }

  test("recoverFailure should propagate successful computations") {
    val x = Random.nextInt()
    val eventuallyResult =
      Async.recoverFailure(Future.successful(x))
    val result = Await.ready(eventuallyResult, 100.milliseconds).value.get
    assertResult(Success(x))(result)
  }

  test("sequenceComputations should start the second computation after the first has completed") {
    try {
      val eventuallyResult =
        Async.sequenceComputations(delay(Success(1)), delay(Success(2)))
      Await.ready(eventuallyResult, 300.milliseconds)
      fail("Asynchronous computations finished too early")
    } catch {
      case _: TimeoutException =>
        ()
    }
  }

  test("sequenceComputations should not start the second computation if the first has failed") {
    val counter = new AtomicInteger(0)
    val eventuallyResult =
      Async.sequenceComputations(
        () => Future.failed(new Exception),
        () => Future.successful { counter.incrementAndGet(); () }
      )
    Await.ready(eventuallyResult, 100.milliseconds)
    assertResult(0)(counter.get())
  }

  test("concurrentComputations should start both computations independently of each otherâ€™s completion") {
    try {
      val eventuallyResult =
        Async.concurrentComputations(delay(Success(1)), delay(Success(2)))
      Await.ready(eventuallyResult, 350.milliseconds)
      ()
    } catch {
      case _: TimeoutException =>
        fail("Asynchronous computations took too much time")
    }
  }

  test("insist should not retry successful computations") {
    val counter = new AtomicInteger(0)
    val eventuallyResult =
      Async.insist(() => Future { counter.incrementAndGet() }, maxAttempts = 3)
    Await.ready(eventuallyResult, 100.milliseconds).value.get
    assertResult(1)(counter.get())
  }

  test("insist should retry failed computations") {
    val counter = new AtomicInteger(0)
    val eventuallyResult =
      Async.insist(
        () => Future { counter.incrementAndGet(); throw new Exception },
        maxAttempts = 3
      )
    Await.ready(eventuallyResult, 200.milliseconds).value.get
    assertResult(3)(counter.get())
  }

}

